<?xml version="1.0" ?>
<robot name="myagv" xmlns:xacro="http://ros.org/wiki/xacro">

  <!-- ****************** ROBOT CONSTANTS *******************************  -->
  <xacro:property name="camera_mass" value="0.1"/>
  <xacro:property name="hokoyu_mass" value="1e-5"/>
  
  <!-- Define the size of the robot's main chassis in meters -->
  <xacro:property name="base_width" value="0.23"/>
  <xacro:property name="base_length" value="0.33115"/>
  <xacro:property name="base_height" value="0.113"/>
	
  <!-- Define intertial property macros  -->
  <xacro:macro name="box_inertia" params="m w h d">
    <inertial>
      <origin xyz="0 0 0" rpy="${pi/2} 0 ${pi/2}"/>
      <mass value="${m}"/>
      <inertia ixx="${(m/12) * (h*h + d*d)}" ixy="0.0" ixz="0.0" iyy="${(m/12) * (w*w + d*d)}" iyz="0.0" izz="${(m/12) * (w*w + h*h)}"/>
    </inertial>
  </xacro:macro>

  <xacro:macro name="cylinder_inertia" params="m r h">
    <inertial>
      <origin xyz="0 0 0" rpy="${pi/2} 0 0" />
      <mass value="${m}"/>
      <inertia ixx="${(m/12) * (3*r*r + h*h)}" ixy = "0" ixz = "0" iyy="${(m/12) * (3*r*r + h*h)}" iyz = "0" izz="${(m/2) * (r*r)}"/>
    </inertial>
  </xacro:macro>

  <xacro:macro name="sphere_inertia" params="m r">
    <inertial>
      <mass value="${m}"/>
      <inertia ixx="${(2/5) * m * (r*r)}" ixy="0.0" ixz="0.0" iyy="${(2/5) * m * (r*r)}" iyz="0.0" izz="${(2/5) * m * (r*r)}"/>
    </inertial>
  </xacro:macro>

  <!-- ****************** ROBOT BASE FOOTPRINT ***************************  -->
  <!-- Define the center of the main robot chassis projected on the ground -->	
  <link name="base_footprint">
    <visual>
        <geometry>
            <mesh filename="package://my_agv_super/meshes/myagv_base.dae" scale="1 1 1"/>
        </geometry>
        <origin xyz="0.0 0.0 0.0" rpy="0.0 0.0 0.0"/>
        <material name="black">
            <color rgba="0.7 0.7 0.0 1.0"/>
        </material>
    </visual>
  </link>

  <!-- The base footprint of the robot is located underneath the chassis -->
  <joint name="base_up" type="continuous">
    <parent link="base_footprint"/>
    <child link="base_up" />
    <origin xyz="0.0 0.0 0.0" rpy="0 0 0"/>
    <axis xyz="0 0 1"/>
  </joint>

  <!-- ********************** ROBOT BASE *********************************  -->
  <link name="base_up">
    <visual>
        <geometry>
            <mesh filename="package://my_agv_super/meshes/myagv_up.dae" scale="1 1 1"/>
        </geometry>
        <origin xyz="0.0 0.0 0.0" rpy="0 0 0"/>
        <material name="black">
            <color rgba="0.7 0.7 0.0 1.0"/>
        </material>
    </visual> 
  
    <collision>
      <geometry>
        <box size="${base_length} ${base_width} ${base_height}"/>
      </geometry>
    </collision>

    <xacro:box_inertia m="40.0" w="${base_width}" d="${base_length}" h="${base_height}"/>
  </link>

  <gazebo reference="base_up">
    <material>Gazebo/Red</material>
  </gazebo>

  <!-- *********************** Lidar SETUP *********************************  -->
  <joint name="base_to_laser" type="fixed">
    <origin xyz="0.065 0.0 0.08" rpy="0 0 3.14159"/>
    <parent link="base_footprint"/>
    <child link="laser_frame"/>
  </joint>

  <link name="laser_frame">
    <visual>
      <geometry>
        <cylinder length="0.1" radius="0.05"/>
      </geometry>
      <material name="black">
        <color rgba="0.1 0.1 0.1 1.0"/>
      </material>
    </visual>
  </link>

  <!-- *********************** IMU SETUP *********************************  -->
  <joint name="base_to_imu" type="fixed">
    <origin xyz="0 0 0" rpy="0 3.14159 3.14159"/>
    <parent link="base_footprint"/>
    <child link="imu"/>
  </joint>

  <link name="imu">
    <visual>
      <geometry>
        <box size="0.04 0.04 0.01"/>
      </geometry>
      <material name="grey">
        <color rgba="0.5 0.5 0.5 1.0"/>
      </material>
    </visual>
  </link>

  <!-- *********************** Camera SETUP *********************************  -->
  <joint name="base_to_camera" type="fixed">
    <origin xyz="0.13 0 0.131" rpy="0 0 0"/>
    <parent link="base_footprint"/>
    <child link="camera_link"/>
  </joint>

  <link name="camera_link">
    <visual>
      <geometry>
        <box size="0.05 0.05 0.05"/>
      </geometry>
      <material name="grey">
        <color rgba="0.5 0.5 0.5 1.0"/>
      </material>
    </visual>
  </link>

</robot>